Workbook

Sheet Content

Sheet Part A
B1: Daily Prices | I1: Log Returns | AB1: Daily Covariance | AL1: Correlation
A2: Date | B2: AAPL | C2: COST | D2: JNJ | E2: JPM | F2: NEE | G2: PG | H2: ^GSPC | I2: AAPL | J2: COST | K2: JNJ | L2: JPM | M2: NEE | N2: PG | O2: ^GSPC | S2: AAPL | T2: COST | U2: JNJ | V2: JPM | W2: NEE | X2: PG | Y2: ^GSPC | AC2: AAPL | AD2: COST | AE2: JNJ | AF2: JPM | AG2: NEE | AH2: PG | AI2: ^GSPC | AM2: AAPL | AN2: COST | AO2: JNJ | AP2: JPM | AQ2: NEE | AR2: PG | AS2: ^GSPC
A3: 44936 | B3: 128.78706 | C3: 462.03519 | D3: 159.89003 | E3: 129.09279 | F3: 77.475365 | G3: 140.8111 | H3: 3919.25 | R3: Daily Return | S3: =AVERAGE(I4:I755) -> 0.00093097769 | T3: =AVERAGE(J4:J755) -> 0.00092290287 | U3: =AVERAGE(K4:K755) -> 0.00032652083 | V3: =AVERAGE(L4:L755) -> 0.0012448187 | W3: =AVERAGE(M4:M755) -> 4.0812061e-05 | X3: =AVERAGE(N4:N755) -> 9.9625826e-06 | Y3: =AVERAGE(O4:O755) -> 0.00076486839 | AB3: AAPL | AC3: =VARP('Part A'!$I$3:$I$755) -> 0.00025524944 | AD3: {=TRANSPOSE(AC4:AC9)} -> 6.6514618e-05 | AE3: 1.0257314e-05 | AF3: 6.9517756e-05 | AG3: 3.7287102e-05 | AH3: 2.3668654e-05 | AI3: 0.00010253729 | AL3: AAPL | AM3: 1 | AN3: {=TRANSPOSE(AM4:AM9)} -> 0.33617744 | AO3: 0.059452546 | AP3: 0.29918965 | AQ3: 0.1352244 | AR3: 0.1432866 | AS3: 0.68182721
A4: 44937 | B4: 131.50606 | C4: 464.82806 | D4: 159.63443 | E4: 130.05217 | F4: 77.896927 | G4: 139.67084 | H4: 3969.6101 | I4: =LN(B4/B3) -> 0.020892546 | J4: =LN(C4/C3) -> 0.0060265323 | K4: =LN(D4/D3) -> -0.0015998777 | L4: =LN(E4/E3) -> 0.0074042381 | M4: =LN(F4/F3) -> 0.0054264918 | N4: =LN(G4/G3) -> -0.0081307559 | O4: =LN(H4/H3) -> 0.012767571 | R4: Annual Return | S4: =S3*252 -> 0.23460638 | T4: =T3*252 -> 0.23257152 | U4: =U3*252 -> 0.082283249 | V4: =V3*252 -> 0.31369431 | W4: =W3*252 -> 0.010284639 | X4: =X3*252 -> 0.0025105708 | Y4: =Y3*252 -> 0.19274683 | AB4: COST | AC4: 6.6514618e-05 | AD4: =VARP('Part A'!$J$3:$J$755) -> 0.00015336713 | AE4: {=TRANSPOSE(AD5:AD9)} -> 1.1619868e-05 | AF4: 4.3485998e-05 | AG4: 2.0615737e-05 | AH4: 3.5350912e-05 | AI4: 5.5491219e-05 | AL4: COST | AM4: 0.33617744 | AN4: 1 | AO4: {=TRANSPOSE(AN5:AN9)} -> 0.086886886 | AP4: 0.24144405 | AQ4: 0.096452067 | AR4: 0.27608886 | AS4: 0.47602856
A5: 44938 | B5: 131.42723 | C5: 463.02371 | D5: 158.83115 | E5: 129.92177 | F5: 77.961075 | G5: 138.88284 | H5: 3983.1699 | I5: =LN(B5/B4) -> -0.00059959625 | J5: =LN(C5/C4) -> -0.0038893154 | K5: =LN(D5/D4) -> -0.0050447235 | L5: =LN(E5/E4) -> -0.00100319 | M5: =LN(F5/F4) -> 0.00082315893 | N5: =LN(G5/G4) -> -0.0056577711 | O5: =LN(H5/H4) -> 0.0034100849 | R5: Daily Std | S5: =_xlfn.STDEV.S(I4:I755) -> 0.015987161 | T5: =_xlfn.STDEV.S(J4:J755) -> 0.012392391 | U5: =_xlfn.STDEV.S(K4:K755) -> 0.01080612 | V5: =_xlfn.STDEV.S(L4:L755) -> 0.014553108 | W5: =_xlfn.STDEV.S(M4:M755) -> 0.017270708 | X5: =_xlfn.STDEV.S(N4:N755) -> 0.010346049 | Y5: =_xlfn.STDEV.S(O4:O755) -> 0.009419201 | AB5: JNJ | AC5: 1.0257314e-05 | AD5: 1.1619868e-05 | AE5: =VARP('Part A'!$K$3:$K$755) -> 0.00011661694 | AF5: {=TRANSPOSE(AE6:AE9)} -> 2.3789911e-05 | AG5: 5.0082259e-05 | AH5: 4.0289905e-05 | AI5: 8.2572266e-06 | AL5: JNJ | AM5: 0.059452546 | AN5: 0.086886886 | AO5: 1 | AP5: {=TRANSPOSE(AO6:AO9)} -> 0.15147648 | AQ5: 0.26870881 | AR5: 0.36085259 | AS5: 0.08123221
A6: 44939 | B6: 132.75719 | C6: 465.73029 | D6: 158.31082 | E6: 133.20027 | F6: 77.603653 | G6: 139.8748 | H6: 3999.0901 | I6: =LN(B6/B5) -> 0.010068476 | J6: =LN(C6/C5) -> 0.0058284135 | K6: =LN(D6/D5) -> -0.0032813391 | L6: =LN(E6/E5) -> 0.024921311 | M6: =LN(F6/F5) -> -0.0045951612 | N6: =LN(G6/G5) -> 0.0071170267 | O6: =LN(H6/H5) -> 0.0039888921 | R6: Annual Std | S6: =S5*SQRT(252) -> 0.25378831 | T6: =T5*SQRT(252) -> 0.1967231 | U6: =U5*SQRT(252) -> 0.17154183 | V6: =V5*SQRT(252) -> 0.23102342 | W6: =W5*SQRT(252) -> 0.27416399 | X6: =X5*SQRT(252) -> 0.16423844 | Y6: =Y5*SQRT(252) -> 0.14952518 | AB6: JPM | AC6: 6.9517756e-05 | AD6: 4.3485998e-05 | AE6: 2.3789911e-05 | AF6: =VARP('Part A'!$L$3:$L$755) -> 0.0002115113 | AG6: {=TRANSPOSE(AF7:AF9)} -> 2.8469214e-05 | AH6: 1.1642316e-05 | AI6: 8.213032e-05 | AL6: JPM | AM6: 0.29918965 | AN6: 0.24144405 | AO6: 0.15147648 | AP6: 1 | AQ6: {=TRANSPOSE(AP7:AP9)} -> 0.11341944 | AR6: 0.077426031 | AS6: 0.59994524
A7: 44943 | B7: 133.91966 | C7: 467.18915 | D7: 157.33412 | E7: 131.14189 | F7: 78.575066 | G7: 139.46687 | H7: 3990.97 | I7: =LN(B7/B6) -> 0.0087182892 | J7: =LN(C7/C6) -> 0.003127523 | K7: =LN(D7/D6) -> -0.0061886177 | L7: =LN(E7/E6) -> -0.015573919 | M7: =LN(F7/F6) -> 0.012439917 | N7: =LN(G7/G6) -> -0.0029206437 | O7: =LN(H7/H6) -> -0.0020325554 | AB7: NEE | AC7: 3.7287102e-05 | AD7: 2.0615737e-05 | AE7: 5.0082259e-05 | AF7: 2.8469214e-05 | AG7: =VARP('Part A'!$M$3:$M$755) -> 0.0002978807 | AH7: {=TRANSPOSE(AG8:AG9)} -> 5.9700694e-05 | AI7: 3.8027351e-05 | AL7: NEE | AM7: 0.1352244 | AN7: 0.096452067 | AO7: 0.26870881 | AP7: 0.11341944 | AQ7: 1 | AR7: {=TRANSPOSE(AQ8:AQ9)} -> 0.33455891 | AS7: 0.23407216
A8: 44944 | B8: 133.20052 | C8: 460.18277 | D8: 154.96078 | E8: 127.20205 | F8: 76.797203 | G8: 135.73082 | H8: 3928.8601 | I8: =LN(B8/B7) -> -0.0053844563 | J8: =LN(C8/C7) -> -0.015110467 | K8: =LN(D8/D7) -> -0.015199623 | L8: =LN(E8/E7) -> -0.030503117 | M8: =LN(F8/F7) -> -0.022886197 | N8: =LN(G8/G7) -> -0.027153447 | O8: =LN(H8/H7) -> -0.015684967 | AB8: PG | AC8: 2.3668654e-05 | AD8: 3.5350912e-05 | AE8: 4.0289905e-05 | AF8: 1.1642316e-05 | AG8: 5.9700694e-05 | AH8: =VARP('Part A'!$N$3:$N$755) -> 0.0001068984 | AI8: =AH9 -> 1.4427467e-05 | AL8: PG | AM8: 0.1432866 | AN8: 0.27608886 | AO8: 0.36085259 | AP8: 0.077426031 | AQ8: 0.33455891 | AR8: 1 | AS8: =AR9 -> 0.14824477
A9: 44945 | B9: 133.25963 | C9: 450.60422 | D9: 154.75085 | E9: 125.50687 | F9: 75.688316 | G9: 132.86037 | H9: 3898.8501 | I9: =LN(B9/B8) -> 0.00044368774 | J9: =LN(C9/C8) -> -0.021034348 | K9: =LN(D9/D8) -> -0.001355651 | L9: =LN(E9/E8) -> -0.013416291 | M9: =LN(F9/F8) -> -0.014544414 | N9: =LN(G9/G8) -> -0.021374954 | O9: =LN(H9/H8) -> -0.0076676719 | AB9: ^GSPC | AC9: 0.00010253729 | AD9: 5.5491219e-05 | AE9: 8.2572266e-06 | AF9: 8.213032e-05 | AG9: 3.8027351e-05 | AH9: 1.4427467e-05 | AI9: =VARP('Part A'!$O$3:$O$755) -> 8.8603368e-05 | AL9: ^GSPC | AM9: 0.68182721 | AN9: 0.47602856 | AO9: 0.08123221 | AP9: 0.59994524 | AQ9: 0.23407216 | AR9: 0.14824477 | AS9: 1
A10: 44946 | B10: 135.82098 | C10: 460.79697 | D10: 154.02974 | E10: 125.81425 | F10: 74.982658 | G10: 133.37346 | H10: 3972.6101 | I10: =LN(B10/B9) -> 0.019038406 | J10: =LN(C10/C9) -> 0.022368139 | K10: =LN(D10/D9) -> -0.0046707367 | L10: =LN(E10/E9) -> 0.0024461809 | M10: =LN(F10/F9) -> -0.0093669417 | N10: =LN(G10/G9) -> 0.0038544514 | O10: =LN(H10/H9) -> 0.018741674
A11: 44949 | B11: 139.01282 | C11: 472.79422 | D11: 153.63719 | E11: 127.854 | F11: 75.761627 | G11: 131.58232 | H11: 4019.8101 | I11: =LN(B11/B10) -> 0.023228417 | J11: =LN(C11/C10) -> 0.025702715 | K11: =LN(D11/D10) -> -0.0025517713 | L11: =LN(E11/E10) -> 0.016082368 | M11: =LN(F11/F10) -> 0.010335062 | N11: =LN(G11/G10) -> -0.013520482 | O11: =LN(H11/H10) -> 0.011811316 | AB11: Annual Covariance
A12: 44950 | B12: 140.41174 | C12: 472.31433 | D12: 153.63719 | E12: 128.95308 | F12: 76.88884 | G12: 132.30061 | H12: 4016.95 | I12: =LN(B12/B11) -> 0.010012989 | J12: =LN(C12/C11) -> -0.0010155214 | K12: =LN(D12/D11) -> 0 | L12: =LN(E12/E11) -> 0.0085595928 | M12: =LN(F12/F11) -> 0.014768812 | N12: =LN(G12/G11) -> 0.0054440353 | O12: =LN(H12/H11) -> -0.00071175636 | AC12: AAPL | AD12: COST | AE12: JNJ | AF12: JPM | AG12: NEE | AH12: PG | AI12: ^GSPC
A13: 44951 | B13: 139.75166 | C13: 471.13379 | D13: 154.7326 | E13: 129.57712 | F13: 70.189705 | G13: 132.20737 | H13: 4016.22 | I13: =LN(B13/B12) -> -0.0047121156 | J13: =LN(C13/C12) -> -0.0025026127 | K13: =LN(D13/D12) -> 0.0071045727 | L13: =LN(E13/E12) -> 0.0048275978 | M13: =LN(F13/F12) -> -0.091159092 | N13: =LN(G13/G12) -> -0.00070505596 | O13: =LN(H13/H12) -> -0.00018174157 | AB13: AAPL | AC13: =AC3*252 -> 0.064322858 | AD13: =AD3*252 -> 0.016761684 | AE13: =AE3*252 -> 0.0025848432 | AF13: =AF3*252 -> 0.017518475 | AG13: =AG3*252 -> 0.0093963498 | AH13: =AH3*252 -> 0.0059645008 | AI13: =AI3*252 -> 0.025839397
A14: 44952 | B14: 141.82047 | C14: 478.25525 | D14: 154.16664 | E14: 130.37813 | F14: 70.015587 | G14: 131.67558 | H14: 4060.4299 | I14: =LN(B14/B13) -> 0.014694914 | J14: =LN(C14/C13) -> 0.015002477 | K14: =LN(D14/D13) -> -0.0036643947 | L14: =LN(E14/E13) -> 0.0061626967 | M14: =LN(F14/F13) -> -0.0024837598 | N14: =LN(G14/G13) -> -0.0040304595 | O14: =LN(H14/H13) -> 0.010947708 | AB14: COST | AC14: =AC4*252 -> 0.016761684 | AD14: =AD4*252 -> 0.038648516 | AE14: =AE4*252 -> 0.0029282067 | AF14: =AF4*252 -> 0.010958471 | AG14: =AG4*252 -> 0.0051951657 | AH14: =AH4*252 -> 0.0089084298 | AI14: =AI4*252 -> 0.013983787
A15: 44953 | B15: 143.76117 | C15: 483.04465 | D15: 153.56416 | E15: 130.69481 | F15: 69.264107 | G15: 131.13455 | H15: 4070.5601 | I15: =LN(B15/B14) -> 0.01359145 | J15: =LN(C15/C14) -> 0.0099645029 | K15: =LN(D15/D14) -> -0.0039156223 | L15: =LN(E15/E14) -> 0.0024259969 | M15: =LN(F15/F14) -> -0.010791055 | N15: =LN(G15/G14) -> -0.0041172815 | O15: =LN(H15/H14) -> 0.002491734 | AB15: JNJ | AC15: =AC5*252 -> 0.0025848432 | AD15: =AD5*252 -> 0.0029282067 | AE15: =AE5*252 -> 0.029387469 | AF15: =AF5*252 -> 0.0059950575 | AG15: =AG5*252 -> 0.012620729 | AH15: =AH5*252 -> 0.010153056 | AI15: =AI5*252 -> 0.0020808211
A16: 44956 | B16: 140.87473 | C16: 483.03497 | D16: 147.87727 | E16: 129.58646 | F16: 68.778397 | G16: 131.545 | H16: 4017.77 | I16: =LN(B16/B15) -> -0.020282354 | J16: =LN(C16/C15) -> -2.0027484e-05 | K16: =LN(D16/D15) -> -0.037735784 | L16: =LN(E16/E15) -> -0.008516628 | M16: =LN(F16/F15) -> -0.0070371391 | N16: =LN(G16/G15) -> 0.0031250739 | O16: =LN(H16/H15) -> -0.013053569 | AB16: JPM | AC16: =AC6*252 -> 0.017518475 | AD16: =AD6*252 -> 0.010958471 | AE16: =AE6*252 -> 0.0059950575 | AF16: =AF6*252 -> 0.053300847 | AG16: =AG6*252 -> 0.007174242 | AH16: =AH6*252 -> 0.0029338636 | AI16: =AI6*252 -> 0.020696841
A17: 44957 | B17: 142.14555 | C17: 490.5788 | D17: 149.17349 | E17: 130.35948 | F17: 68.393501 | G17: 132.82303 | H17: 4076.6001 | I17: =LN(B17/B16) -> 0.0089805352 | J17: =LN(C17/C16) -> 0.015496852 | K17: =LN(D17/D16) -> 0.0087273103 | L17: =LN(E17/E16) -> 0.0059476043 | M17: =LN(F17/F16) -> -0.0056118832 | N17: =LN(G17/G16) -> 0.0096686454 | O17: =LN(H17/H16) -> 0.014536304 | AB17: NEE | AC17: =AC7*252 -> 0.0093963498 | AD17: =AD7*252 -> 0.0051951657 | AE17: =AE7*252 -> 0.012620729 | AF17: =AF7*252 -> 0.007174242 | AG17: =AG7*252 -> 0.075065937 | AH17: =AH7*252 -> 0.015044575 | AI17: =AI7*252 -> 0.0095828924
A18: 44958 | B18: 143.26862 | C18: 497.07657 | D18: 150.54272 | E18: 130.01489 | F18: 68.036079 | G18: 133.57867 | H18: 4119.21 | I18: =LN(B18/B17) -> 0.0078697419 | J18: =LN(C18/C17) -> 0.013158165 | K18: =LN(D18/D17) -> 0.009136921 | L18: =LN(E18/E17) -> -0.0026468767 | M18: =LN(F18/F17) -> -0.0052396656 | N18: =LN(G18/G17) -> 0.0056729951 | O18: =LN(H18/H17) -> 0.010398056 | AB18: PG | AC18: =AC8*252 -> 0.0059645008 | AD18: =AD8*252 -> 0.0089084298 | AE18: =AE8*252 -> 0.010153056 | AF18: =AF8*252 -> 0.0029338636 | AG18: =AG8*252 -> 0.015044575 | AH18: =AH8*252 -> 0.026938396 | AI18: =AI8*252 -> 0.0036357217
A19: 44959 | B19: 148.57854 | C19: 503.24899 | D19: 151.10867 | E19: 129.40947 | F19: 69.282433 | G19: 132.62714 | H19: 4179.7598 | I19: =LN(B19/B18) -> 0.036392387 | J19: =LN(C19/C18) -> 0.012340988 | K19: =LN(D19/D18) -> 0.003752339 | L19: =LN(E19/E18) -> -0.0046674419 | M19: =LN(F19/F18) -> 0.018153232 | N19: =LN(G19/G18) -> -0.0071489209 | O19: =LN(H19/H18) -> 0.014592385 | AB19: ^GSPC | AC19: =AC9*252 -> 0.025839397 | AD19: =AD9*252 -> 0.013983787 | AE19: =AE9*252 -> 0.0020808211 | AF19: =AF9*252 -> 0.020696841 | AG19: =AG9*252 -> 0.0095828924 | AH19: =AH9*252 -> 0.0036357217 | AI19: =AI9*252 -> 0.022328049
A20: 44960 | B20: 152.20383 | C20: 494.95175 | D20: 150.25975 | E20: 131.412 | F20: 68.430153 | G20: 133.0376 | H20: 4136.48 | I20: =LN(B20/B19) -> 0.024106902 | J20: =LN(C20/C19) -> -0.016624777 | K20: =LN(D20/D19) -> -0.0056338017 | L20: =LN(E20/E19) -> 0.015355885 | M20: =LN(F20/F19) -> -0.012377816 | N20: =LN(G20/G19) -> 0.0030900733 | O20: =LN(H20/H19) -> -0.010408593
A21: 44963 | B21: 149.47498 | C21: 495.7113 | D21: 149.11871 | E21: 132.18503 | F21: 69.199974 | G21: 131.90883 | H21: 4111.0801 | I21: =LN(B21/B20) -> -0.018091598 | J21: =LN(C21/C20) -> 0.0015334218 | K21: =LN(D21/D20) -> -0.0076227428 | L21: =LN(E21/E20) -> 0.0058652233 | M21: =LN(F21/F20) -> 0.011186929 | N21: =LN(G21/G20) -> -0.0085207849 | O21: =LN(H21/H20) -> -0.0061593932
A22: 44964 | B22: 152.35156 | C22: 496.61505 | D22: 149.15524 | E22: 133.79636 | F22: 69.722321 | G22: 130.62144 | H22: 4164 | I22: =LN(B22/B21) -> 0.01906177 | J22: =LN(C22/C21) -> 0.001821473 | K22: =LN(D22/D21) -> 0.00024493953 | L22: =LN(E22/E21) -> 0.012116245 | M22: =LN(F22/F21) -> 0.0075200163 | N22: =LN(G22/G21) -> -0.0098075878 | O22: =LN(H22/H21) -> 0.012790364
A23: 44965 | B23: 149.66217 | C23: 484.38541 | D23: 149.34692 | E23: 132.85567 | F23: 68.760071 | G23: 129.26877 | H23: 4117.8599 | I23: =LN(B23/B22) -> -0.017810205 | J23: =LN(C23/C22) -> -0.024934297 | K23: =LN(D23/D22) -> 0.001284285 | L23: =LN(E23/E22) -> -0.0070555849 | M23: =LN(F23/F22) -> -0.013897294 | N23: =LN(G23/G22) -> -0.010409693 | O23: =LN(H23/H22) -> -0.011142573 | AB23: Part A. b - done in the Colab sheet
A24: 44966 | B24: 148.62776 | C24: 481.32806 | D24: 147.32962 | E24: 130.78795 | F24: 67.147133 | G24: 127.85085 | H24: 4081.5 | I24: =LN(B24/B23) -> -0.0069356194 | J24: =LN(C24/C23) -> -0.006331801 | K24: =LN(D24/D23) -> -0.013599555 | L24: =LN(E24/E23) -> -0.015686031 | M24: =LN(F24/F23) -> -0.023736985 | N24: =LN(G24/G23) -> -0.011029339 | O24: =LN(H24/H23) -> -0.0088690098 | AB24: Part A. c - included in the report.
A25: 44967 | B25: 148.99283 | C25: 480.71268 | D25: 148.01419 | E25: 131.36542 | F25: 68.494301 | G25: 128.9796 | H25: 4090.46 | I25: =LN(B25/B24) -> 0.0024532356 | J25: =LN(C25/C24) -> -0.0012793368 | K25: =LN(D25/D24) -> 0.0046357602 | L25: =LN(E25/E24) -> 0.0044055876 | M25: =LN(F25/F24) -> 0.019864318 | N25: =LN(G25/G24) -> 0.0087898712 | O25: =LN(H25/H24) -> 0.0021928557
A26: 44970 | B26: 151.79488 | C26: 486.92368 | D26: 148.56192 | E26: 132.79048 | F26: 69.300774 | G26: 130.66814 | H26: 4137.29 | I26: =LN(B26/B25) -> 0.018631937 | J26: =LN(C26/C25) -> 0.012837641 | K26: =LN(D26/D25) -> 0.0036936901 | L26: =LN(E26/E25) -> 0.010789673 | M26: =LN(F26/F25) -> 0.011705527 | N26: =LN(G26/G25) -> 0.013006556 | O26: =LN(H26/H25) -> 0.01138357
A27: 44971 | B27: 151.15358 | C27: 483.81821 | D27: 147.91379 | E27: 133.37726 | F27: 69.676491 | G27: 129.93114 | H27: 4136.1299 | I27: =LN(B27/B26) -> -0.004233706 | J27: =LN(C27/C26) -> -0.0063981567 | K27: =LN(D27/D26) -> -0.0043722527 | L27: =LN(E27/E26) -> 0.0044090819 | M27: =LN(F27/F26) -> 0.0054068999 | N27: =LN(G27/G26) -> -0.0056562051 | O27: =LN(H27/H26) -> -0.00028045386
A28: 44972 | B28: 153.25513 | C28: 491.56744 | D28: 145.47655 | E28: 133.93613 | F28: 70.510468 | G28: 129.63261 | H28: 4147.6001 | I28: =LN(B28/B27) -> 0.013807625 | J28: =LN(C28/C27) -> 0.01588992 | K28: =LN(D28/D27) -> -0.016614703 | L28: =LN(E28/E27) -> 0.0041813785 | M28: =LN(F28/F27) -> 0.011898205 | N28: =LN(G28/G27) -> -0.0023001908 | O28: =LN(H28/H27) -> 0.0027693375
A29: 44973 | B29: 151.65677 | C29: 484.66434 | D29: 144.44507 | E29: 132.09192 | F29: 69.364929 | G29: 127.93477 | H29: 4090.4099 | I29: =LN(B29/B28) -> -0.010484162 | J29: =LN(C29/C28) -> -0.014142588 | K29: =LN(D29/D28) -> -0.0071156008 | L29: =LN(E29/E28) -> -0.013864984 | M29: =LN(F29/F28) -> -0.016379778 | N29: =LN(G29/G28) -> -0.01318389 | O29: =LN(H29/H28) -> -0.013884689
A30: 44974 | B30: 150.51227 | C30: 487.91394 | D30: 147.46065 | E30: 132.48309 | F30: 69.713173 | G30: 130.61214 | H30: 4079.0901 | I30: =LN(B30/B29) -> -0.0075752712 | J30: =LN(C30/C29) -> 0.0066824757 | K30: =LN(D30/D29) -> 0.020662059 | L30: =LN(E30/E29) -> 0.0029570034 | M30: =LN(F30/F29) -> 0.0050078975 | N30: =LN(G30/G29) -> 0.02071163 | O30: =LN(H30/H29) -> -0.0027712422
A31: 44978 | B31: 146.49661 | C31: 482.39526 | D31: 145.26334 | E31: 130.05217 | F31: 67.504562 | G31: 130.51883 | H31: 3997.3401 | I31: =LN(B31/B30) -> -0.027042291 | J31: =LN(C31/C30) -> -0.011375212 | K31: =LN(D31/D30) -> -0.015013137 | L31: =LN(E31/E30) -> -0.018519363 | M31: =LN(F31/F30) -> -0.032194108 | N31: =LN(G31/G30) -> -0.0007146414 | O31: =LN(H31/H30) -> -0.020244784
A32: 44979 | B32: 146.9209 | C32: 478.21295 | D32: 145.06107 | E32: 129.05551 | F32: 67.522881 | G32: 131.06926 | H32: 3991.05 | I32: =LN(B32/B31) -> 0.0028920304 | J32: =LN(C32/C31) -> -0.0087076883 | K32: =LN(D32/D31) -> -0.0013934105 | L32: =LN(E32/E31) -> -0.0076930428 | M32: =LN(F32/F31) -> 0.00027132524 | N32: =LN(G32/G31) -> 0.0042083805 | O32: =LN(H32/H31) -> -0.0015747955
A33: 44980 | B33: 147.40433 | C33: 474.12677 | D33: 145.01509 | E33: 130.08939 | F33: 66.780579 | G33: 130.64944 | H33: 4012.3201 | I33: =LN(B33/B32) -> 0.0032850014 | J33: =LN(C33/C32) -> -0.0085814056 | K33: =LN(D33/D32) -> -0.00031698387 | L33: =LN(E33/E32) -> 0.0079791654 | M33: =LN(F33/F32) -> -0.011054213 | N33: =LN(G33/G32) -> -0.0032081423 | O33: =LN(H33/H32) -> 0.0053152783
A34: 44981 | B34: 144.75027 | C34: 469.77145 | D34: 143.39696 | E34: 131.26297 | F34: 66.826393 | G34: 129.91246 | H34: 3970.04 | I34: =LN(B34/B33) -> -0.018169324 | J34: =LN(C34/C33) -> -0.0092284252 | K34: =LN(D34/D33) -> -0.011221102 | L34: =LN(E34/E33) -> 0.0089809167 | M34: =LN(F34/F33) -> 0.00068581026 | N34: =LN(G34/G33) -> -0.0056568992 | O34: =LN(H34/H33) -> -0.010593465
A35: 44984 | B35: 145.94409 | C35: 468.25244 | D35: 143.08438 | E35: 132.4086 | F35: 66.280357 | G35: 129.80052 | H35: 3982.24 | I35: =LN(B35/B34) -> 0.0082136016 | J35: =LN(C35/C34) -> -0.0032387528 | K35: =LN(D35/D34) -> -0.0021821765 | L35: =LN(E35/E34) -> 0.0086898796 | M35: =LN(F35/F34) -> -0.008204525 | N35: =LN(G35/G34) -> -0.00086201685 | O35: =LN(H35/H34) -> 0.0030682925
A36: 44985 | B36: 145.44092 | C36: 465.51227 | D36: 140.90541 | E36: 133.51695 | F36: 65.514801 | G36: 128.32655 | H36: 3970.1499 | I36: =LN(B36/B35) -> -0.0034536734 | J36: =LN(C36/C35) -> -0.0058691042 | K36: =LN(D36/D35) -> -0.015345714 | L36: =LN(E36/E35) -> 0.0083358599 | M36: =LN(F36/F35) -> -0.011617497 | N36: =LN(G36/G35) -> -0.011420612 | O36: =LN(H36/H35) -> -0.0030406198
... A755: 46031 | B755: 259.37 | C755: 924.88 | D755: 204.39 | E755: 329.19 | F755: 79.889999 | G755: 141.87 | H755: 6966.2798 | I755: =LN(B755/B754) -> 0.0012730719 | J755: =LN(C755/C754) -> 0.010401202 | K755: =LN(D755/D754) -> -0.0066319091 | L755: =LN(E755/E754) -> -0.0018210151 | M755: =LN(F755/F754) -> 0.0050194801 | N755: =LN(G755/G754) -> 0.0023994108 | O755: =LN(H755/H754) -> 0.0064546111

Sheet Part B
B1: Daily Prices | I1: Log Returns | AB1: Daily Covariance | AL1: Correlation
A2: Date | B2: AAPL | C2: COST | D2: JNJ | E2: JPM | F2: NEE | G2: PG | H2: ^GSPC | I2: AAPL | J2: COST | K2: JNJ | L2: JPM | M2: NEE | N2: PG | O2: ^GSPC | S2: AAPL | T2: COST | U2: JNJ | V2: JPM | W2: NEE | X2: PG | Y2: ^GSPC | AC2: AAPL | AD2: COST | AE2: JNJ | AF2: JPM | AG2: NEE | AH2: PG | AI2: ^GSPC | AM2: AAPL | AN2: COST | AO2: JNJ | AP2: JPM | AQ2: NEE | AR2: PG | AS2: ^GSPC
A3: 44936 | B3: 128.78706 | C3: 462.03519 | D3: 159.89003 | E3: 129.09279 | F3: 77.475365 | G3: 140.8111 | H3: 3919.25 | R3: Daily Return | S3: =AVERAGE(I4:I755) -> 0.00093097769 | T3: =AVERAGE(J4:J755) -> 0.00092290287 | U3: =AVERAGE(K4:K755) -> 0.00032652083 | V3: =AVERAGE(L4:L755) -> 0.0012448187 | W3: =AVERAGE(M4:M755) -> 4.0812061e-05 | X3: =AVERAGE(N4:N755) -> 9.9625826e-06 | Y3: =AVERAGE(O4:O755) -> 0.00076486839 | AB3: AAPL | AC3: =VARP('Part B'!$I$3:$I$755) -> 0.00025524944 | AD3: {=TRANSPOSE(AC4:AC9)} -> 6.6514618e-05 | AE3: 1.0257314e-05 | AF3: 6.9517756e-05 | AG3: 3.7287102e-05 | AH3: 2.3668654e-05 | AI3: 0.00010253729 | AL3: AAPL | AM3: 1 | AN3: {=TRANSPOSE(AM4:AM9)} -> 0.33617744 | AO3: 0.059452546 | AP3: 0.29918965 | AQ3: 0.1352244 | AR3: 0.1432866 | AS3: 0.68182721
A4: 44937 | B4: 131.50606 | C4: 464.82806 | D4: 159.63443 | E4: 130.05217 | F4: 77.896927 | G4: 139.67084 | H4: 3969.6101 | I4: =LN(B4/B3) -> 0.020892546 | J4: =LN(C4/C3) -> 0.0060265323 | K4: =LN(D4/D3) -> -0.0015998777 | L4: =LN(E4/E3) -> 0.0074042381 | M4: =LN(F4/F3) -> 0.0054264918 | N4: =LN(G4/G3) -> -0.0081307559 | O4: =LN(H4/H3) -> 0.012767571 | R4: Annual Return | S4: =S3*252 -> 0.23460638 | T4: =T3*252 -> 0.23257152 | U4: =U3*252 -> 0.082283249 | V4: =V3*252 -> 0.31369431 | W4: =W3*252 -> 0.010284639 | X4: =X3*252 -> 0.0025105708 | Y4: =Y3*252 -> 0.19274683 | AB4: COST | AC4: 6.6514618e-05 | AD4: =VARP('Part B'!$J$3:$J$755) -> 0.00015336713 | AE4: {=TRANSPOSE(AD5:AD9)} -> 1.1619868e-05 | AF4: 4.3485998e-05 | AG4: 2.0615737e-05 | AH4: 3.5350912e-05 | AI4: 5.5491219e-05 | AL4: COST | AM4: 0.33617744 | AN4: 1 | AO4: {=TRANSPOSE(AN5:AN9)} -> 0.086886886 | AP4: 0.24144405 | AQ4: 0.096452067 | AR4: 0.27608886 | AS4: 0.47602856
A5: 44938 | B5: 131.42723 | C5: 463.02371 | D5: 158.83115 | E5: 129.92177 | F5: 77.961075 | G5: 138.88284 | H5: 3983.1699 | I5: =LN(B5/B4) -> -0.00059959625 | J5: =LN(C5/C4) -> -0.0038893154 | K5: =LN(D5/D4) -> -0.0050447235 | L5: =LN(E5/E4) -> -0.00100319 | M5: =LN(F5/F4) -> 0.00082315893 | N5: =LN(G5/G4) -> -0.0056577711 | O5: =LN(H5/H4) -> 0.0034100849 | R5: Daily Std | S5: =_xlfn.STDEV.S(I4:I755) -> 0.015987161 | T5: =_xlfn.STDEV.S(J4:J755) -> 0.012392391 | U5: =_xlfn.STDEV.S(K4:K755) -> 0.01080612 | V5: =_xlfn.STDEV.S(L4:L755) -> 0.014553108 | W5: =_xlfn.STDEV.S(M4:M755) -> 0.017270708 | X5: =_xlfn.STDEV.S(N4:N755) -> 0.010346049 | Y5: =_xlfn.STDEV.S(O4:O755) -> 0.009419201 | AB5: JNJ | AC5: 1.0257314e-05 | AD5: 1.1619868e-05 | AE5: =VARP('Part B'!$K$3:$K$755) -> 0.00011661694 | AF5: {=TRANSPOSE(AE6:AE9)} -> 2.3789911e-05 | AG5: 5.0082259e-05 | AH5: 4.0289905e-05 | AI5: 8.2572266e-06 | AL5: JNJ | AM5: 0.059452546 | AN5: 0.086886886 | AO5: 1 | AP5: {=TRANSPOSE(AO6:AO9)} -> 0.15147648 | AQ5: 0.26870881 | AR5: 0.36085259 | AS5: 0.08123221
A6: 44939 | B6: 132.75719 | C6: 465.73029 | D6: 158.31082 | E6: 133.20027 | F6: 77.603653 | G6: 139.8748 | H6: 3999.0901 | I6: =LN(B6/B5) -> 0.010068476 | J6: =LN(C6/C5) -> 0.0058284135 | K6: =LN(D6/D5) -> -0.0032813391 | L6: =LN(E6/E5) -> 0.024921311 | M6: =LN(F6/F5) -> -0.0045951612 | N6: =LN(G6/G5) -> 0.0071170267 | O6: =LN(H6/H5) -> 0.0039888921 | R6: Annual Std | S6: =S5*SQRT(252) -> 0.25378831 | T6: =T5*SQRT(252) -> 0.1967231 | U6: =U5*SQRT(252) -> 0.17154183 | V6: =V5*SQRT(252) -> 0.23102342 | W6: =W5*SQRT(252) -> 0.27416399 | X6: =X5*SQRT(252) -> 0.16423844 | Y6: =Y5*SQRT(252) -> 0.14952518 | AB6: JPM | AC6: 6.9517756e-05 | AD6: 4.3485998e-05 | AE6: 2.3789911e-05 | AF6: =VARP('Part B'!$L$3:$L$755) -> 0.0002115113 | AG6: {=TRANSPOSE(AF7:AF9)} -> 2.8469214e-05 | AH6: 1.1642316e-05 | AI6: 8.213032e-05 | AL6: JPM | AM6: 0.29918965 | AN6: 0.24144405 | AO6: 0.15147648 | AP6: 1 | AQ6: {=TRANSPOSE(AP7:AP9)} -> 0.11341944 | AR6: 0.077426031 | AS6: 0.59994524
A7: 44943 | B7: 133.91966 | C7: 467.18915 | D7: 157.33412 | E7: 131.14189 | F7: 78.575066 | G7: 139.46687 | H7: 3990.97 | I7: =LN(B7/B6) -> 0.0087182892 | J7: =LN(C7/C6) -> 0.003127523 | K7: =LN(D7/D6) -> -0.0061886177 | L7: =LN(E7/E6) -> -0.015573919 | M7: =LN(F7/F6) -> 0.012439917 | N7: =LN(G7/G6) -> -0.0029206437 | O7: =LN(H7/H6) -> -0.0020325554 | AB7: NEE | AC7: 3.7287102e-05 | AD7: 2.0615737e-05 | AE7: 5.0082259e-05 | AF7: 2.8469214e-05 | AG7: =VARP('Part B'!$M$3:$M$755) -> 0.0002978807 | AH7: {=TRANSPOSE(AG8:AG9)} -> 5.9700694e-05 | AI7: 3.8027351e-05 | AL7: NEE | AM7: 0.1352244 | AN7: 0.096452067 | AO7: 0.26870881 | AP7: 0.11341944 | AQ7: 1 | AR7: {=TRANSPOSE(AQ8:AQ9)} -> 0.33455891 | AS7: 0.23407216
A8: 44944 | B8: 133.20052 | C8: 460.18277 | D8: 154.96078 | E8: 127.20205 | F8: 76.797203 | G8: 135.73082 | H8: 3928.8601 | I8: =LN(B8/B7) -> -0.0053844563 | J8: =LN(C8/C7) -> -0.015110467 | K8: =LN(D8/D7) -> -0.015199623 | L8: =LN(E8/E7) -> -0.030503117 | M8: =LN(F8/F7) -> -0.022886197 | N8: =LN(G8/G7) -> -0.027153447 | O8: =LN(H8/H7) -> -0.015684967 | AB8: PG | AC8: 2.3668654e-05 | AD8: 3.5350912e-05 | AE8: 4.0289905e-05 | AF8: 1.1642316e-05 | AG8: 5.9700694e-05 | AH8: =VARP('Part B'!$N$3:$N$755) -> 0.0001068984 | AI8: =AH9 -> 1.4427467e-05 | AL8: PG | AM8: 0.1432866 | AN8: 0.27608886 | AO8: 0.36085259 | AP8: 0.077426031 | AQ8: 0.33455891 | AR8: 1 | AS8: =AR9 -> 0.14824477
A9: 44945 | B9: 133.25963 | C9: 450.60422 | D9: 154.75085 | E9: 125.50687 | F9: 75.688316 | G9: 132.86037 | H9: 3898.8501 | I9: =LN(B9/B8) -> 0.00044368774 | J9: =LN(C9/C8) -> -0.021034348 | K9: =LN(D9/D8) -> -0.001355651 | L9: =LN(E9/E8) -> -0.013416291 | M9: =LN(F9/F8) -> -0.014544414 | N9: =LN(G9/G8) -> -0.021374954 | O9: =LN(H9/H8) -> -0.0076676719 | AB9: ^GSPC | AC9: 0.00010253729 | AD9: 5.5491219e-05 | AE9: 8.2572266e-06 | AF9: 8.213032e-05 | AG9: 3.8027351e-05 | AH9: 1.4427467e-05 | AI9: =VARP('Part B'!$O$3:$O$755) -> 8.8603368e-05 | AL9: ^GSPC | AM9: 0.68182721 | AN9: 0.47602856 | AO9: 0.08123221 | AP9: 0.59994524 | AQ9: 0.23407216 | AR9: 0.14824477 | AS9: 1
A10: 44946 | B10: 135.82098 | C10: 460.79697 | D10: 154.02974 | E10: 125.81425 | F10: 74.982658 | G10: 133.37346 | H10: 3972.6101 | I10: =LN(B10/B9) -> 0.019038406 | J10: =LN(C10/C9) -> 0.022368139 | K10: =LN(D10/D9) -> -0.0046707367 | L10: =LN(E10/E9) -> 0.0024461809 | M10: =LN(F10/F9) -> -0.0093669417 | N10: =LN(G10/G9) -> 0.0038544514 | O10: =LN(H10/H9) -> 0.018741674
A11: 44949 | B11: 139.01282 | C11: 472.79422 | D11: 153.63719 | E11: 127.854 | F11: 75.761627 | G11: 131.58232 | H11: 4019.8101 | I11: =LN(B11/B10) -> 0.023228417 | J11: =LN(C11/C10) -> 0.025702715 | K11: =LN(D11/D10) -> -0.0025517713 | L11: =LN(E11/E10) -> 0.016082368 | M11: =LN(F11/F10) -> 0.010335062 | N11: =LN(G11/G10) -> -0.013520482 | O11: =LN(H11/H10) -> 0.011811316 | AB11: Annual Covariance
A12: 44950 | B12: 140.41174 | C12: 472.31433 | D12: 153.63719 | E12: 128.95308 | F12: 76.88884 | G12: 132.30061 | H12: 4016.95 | I12: =LN(B12/B11) -> 0.010012989 | J12: =LN(C12/C11) -> -0.0010155214 | K12: =LN(D12/D11) -> 0 | L12: =LN(E12/E11) -> 0.0085595928 | M12: =LN(F12/F11) -> 0.014768812 | N12: =LN(G12/G11) -> 0.0054440353 | O12: =LN(H12/H11) -> -0.00071175636 | AC12: AAPL | AD12: COST | AE12: JNJ | AF12: JPM | AG12: NEE | AH12: PG | AI12: ^GSPC
A13: 44951 | B13: 139.75166 | C13: 471.13379 | D13: 154.7326 | E13: 129.57712 | F13: 70.189705 | G13: 132.20737 | H13: 4016.22 | I13: =LN(B13/B12) -> -0.0047121156 | J13: =LN(C13/C12) -> -0.0025026127 | K13: =LN(D13/D12) -> 0.0071045727 | L13: =LN(E13/E12) -> 0.0048275978 | M13: =LN(F13/F12) -> -0.091159092 | N13: =LN(G13/G12) -> -0.00070505596 | O13: =LN(H13/H12) -> -0.00018174157 | AB13: AAPL | AC13: =AC3*252 -> 0.064322858 | AD13: =AD3*252 -> 0.016761684 | AE13: =AE3*252 -> 0.0025848432 | AF13: =AF3*252 -> 0.017518475 | AG13: =AG3*252 -> 0.0093963498 | AH13: =AH3*252 -> 0.0059645008 | AI13: =AI3*252 -> 0.025839397
A14: 44952 | B14: 141.82047 | C14: 478.25525 | D14: 154.16664 | E14: 130.37813 | F14: 70.015587 | G14: 131.67558 | H14: 4060.4299 | I14: =LN(B14/B13) -> 0.014694914 | J14: =LN(C14/C13) -> 0.015002477 | K14: =LN(D14/D13) -> -0.0036643947 | L14: =LN(E14/E13) -> 0.0061626967 | M14: =LN(F14/F13) -> -0.0024837598 | N14: =LN(G14/G13) -> -0.0040304595 | O14: =LN(H14/H13) -> 0.010947708 | AB14: COST | AC14: =AC4*252 -> 0.016761684 | AD14: =AD4*252 -> 0.038648516 | AE14: =AE4*252 -> 0.0029282067 | AF14: =AF4*252 -> 0.010958471 | AG14: =AG4*252 -> 0.0051951657 | AH14: =AH4*252 -> 0.0089084298 | AI14: =AI4*252 -> 0.013983787
A15: 44953 | B15: 143.76117 | C15: 483.04465 | D15: 153.56416 | E15: 130.69481 | F15: 69.264107 | G15: 131.13455 | H15: 4070.5601 | I15: =LN(B15/B14) -> 0.01359145 | J15: =LN(C15/C14) -> 0.0099645029 | K15: =LN(D15/D14) -> -0.0039156223 | L15: =LN(E15/E14) -> 0.0024259969 | M15: =LN(F15/F14) -> -0.010791055 | N15: =LN(G15/G14) -> -0.0041172815 | O15: =LN(H15/H14) -> 0.002491734 | AB15: JNJ | AC15: =AC5*252 -> 0.0025848432 | AD15: =AD5*252 -> 0.0029282067 | AE15: =AE5*252 -> 0.029387469 | AF15: =AF5*252 -> 0.0059950575 | AG15: =AG5*252 -> 0.012620729 | AH15: =AH5*252 -> 0.010153056 | AI15: =AI5*252 -> 0.0020808211
A16: 44956 | B16: 140.87473 | C16: 483.03497 | D16: 147.87727 | E16: 129.58646 | F16: 68.778397 | G16: 131.545 | H16: 4017.77 | I16: =LN(B16/B15) -> -0.020282354 | J16: =LN(C16/C15) -> -2.0027484e-05 | K16: =LN(D16/D15) -> -0.037735784 | L16: =LN(E16/E15) -> -0.008516628 | M16: =LN(F16/F15) -> -0.0070371391 | N16: =LN(G16/G15) -> 0.0031250739 | O16: =LN(H16/H15) -> -0.013053569 | AB16: JPM | AC16: =AC6*252 -> 0.017518475 | AD16: =AD6*252 -> 0.010958471 | AE16: =AE6*252 -> 0.0059950575 | AF16: =AF6*252 -> 0.053300847 | AG16: =AG6*252 -> 0.007174242 | AH16: =AH6*252 -> 0.0029338636 | AI16: =AI6*252 -> 0.020696841
A17: 44957 | B17: 142.14555 | C17: 490.5788 | D17: 149.17349 | E17: 130.35948 | F17: 68.393501 | G17: 132.82303 | H17: 4076.6001 | I17: =LN(B17/B16) -> 0.0089805352 | J17: =LN(C17/C16) -> 0.015496852 | K17: =LN(D17/D16) -> 0.0087273103 | L17: =LN(E17/E16) -> 0.0059476043 | M17: =LN(F17/F16) -> -0.0056118832 | N17: =LN(G17/G16) -> 0.0096686454 | O17: =LN(H17/H16) -> 0.014536304 | AB17: NEE | AC17: =AC7*252 -> 0.0093963498 | AD17: =AD7*252 -> 0.0051951657 | AE17: =AE7*252 -> 0.012620729 | AF17: =AF7*252 -> 0.007174242 | AG17: =AG7*252 -> 0.075065937 | AH17: =AH7*252 -> 0.015044575 | AI17: =AI7*252 -> 0.0095828924
A18: 44958 | B18: 143.26862 | C18: 497.07657 | D18: 150.54272 | E18: 130.01489 | F18: 68.036079 | G18: 133.57867 | H18: 4119.21 | I18: =LN(B18/B17) -> 0.0078697419 | J18: =LN(C18/C17) -> 0.013158165 | K18: =LN(D18/D17) -> 0.009136921 | L18: =LN(E18/E17) -> -0.0026468767 | M18: =LN(F18/F17) -> -0.0052396656 | N18: =LN(G18/G17) -> 0.0056729951 | O18: =LN(H18/H17) -> 0.010398056 | AB18: PG | AC18: =AC8*252 -> 0.0059645008 | AD18: =AD8*252 -> 0.0089084298 | AE18: =AE8*252 -> 0.010153056 | AF18: =AF8*252 -> 0.0029338636 | AG18: =AG8*252 -> 0.015044575 | AH18: =AH8*252 -> 0.026938396 | AI18: =AI8*252 -> 0.0036357217
A19: 44959 | B19: 148.57854 | C19: 503.24899 | D19: 151.10867 | E19: 129.40947 | F19: 69.282433 | G19: 132.62714 | H19: 4179.7598 | I19: =LN(B19/B18) -> 0.036392387 | J19: =LN(C19/C18) -> 0.012340988 | K19: =LN(D19/D18) -> 0.003752339 | L19: =LN(E19/E18) -> -0.0046674419 | M19: =LN(F19/F18) -> 0.018153232 | N19: =LN(G19/G18) -> -0.0071489209 | O19: =LN(H19/H18) -> 0.014592385 | AB19: ^GSPC | AC19: =AC9*252 -> 0.025839397 | AD19: =AD9*252 -> 0.013983787 | AE19: =AE9*252 -> 0.0020808211 | AF19: =AF9*252 -> 0.020696841 | AG19: =AG9*252 -> 0.0095828924 | AH19: =AH9*252 -> 0.0036357217 | AI19: =AI9*252 -> 0.022328049
A20: 44960 | B20: 152.20383 | C20: 494.95175 | D20: 150.25975 | E20: 131.412 | F20: 68.430153 | G20: 133.0376 | H20: 4136.48 | I20: =LN(B20/B19) -> 0.024106902 | J20: =LN(C20/C19) -> -0.016624777 | K20: =LN(D20/D19) -> -0.0056338017 | L20: =LN(E20/E19) -> 0.015355885 | M20: =LN(F20/F19) -> -0.012377816 | N20: =LN(G20/G19) -> 0.0030900733 | O20: =LN(H20/H19) -> -0.010408593
A21: 44963 | B21: 149.47498 | C21: 495.7113 | D21: 149.11871 | E21: 132.18503 | F21: 69.199974 | G21: 131.90883 | H21: 4111.0801 | I21: =LN(B21/B20) -> -0.018091598 | J21: =LN(C21/C20) -> 0.0015334218 | K21: =LN(D21/D20) -> -0.0076227428 | L21: =LN(E21/E20) -> 0.0058652233 | M21: =LN(F21/F20) -> 0.011186929 | N21: =LN(G21/G20) -> -0.0085207849 | O21: =LN(H21/H20) -> -0.0061593932
A22: 44964 | B22: 152.35156 | C22: 496.61505 | D22: 149.15524 | E22: 133.79636 | F22: 69.722321 | G22: 130.62144 | H22: 4164 | I22: =LN(B22/B21) -> 0.01906177 | J22: =LN(C22/C21) -> 0.001821473 | K22: =LN(D22/D21) -> 0.00024493953 | L22: =LN(E22/E21) -> 0.012116245 | M22: =LN(F22/F21) -> 0.0075200163 | N22: =LN(G22/G21) -> -0.0098075878 | O22: =LN(H22/H21) -> 0.012790364 | V22: PART B | AB22: Risk free return | AC22: 0.0417
A23: 44965 | B23: 149.66217 | C23: 484.38541 | D23: 149.34692 | E23: 132.85567 | F23: 68.760071 | G23: 129.26877 | H23: 4117.8599 | I23: =LN(B23/B22) -> -0.017810205 | J23: =LN(C23/C22) -> -0.024934297 | K23: =LN(D23/D22) -> 0.001284285 | L23: =LN(E23/E22) -> -0.0070555849 | M23: =LN(F23/F22) -> -0.013897294 | N23: =LN(G23/G22) -> -0.010409693 | O23: =LN(H23/H22) -> -0.011142573 | Z23: Without short selling
A24: 44966 | B24: 148.62776 | C24: 481.32806 | D24: 147.32962 | E24: 130.78795 | F24: 67.147133 | G24: 127.85085 | H24: 4081.5 | I24: =LN(B24/B23) -> -0.0069356194 | J24: =LN(C24/C23) -> -0.006331801 | K24: =LN(D24/D23) -> -0.013599555 | L24: =LN(E24/E23) -> -0.015686031 | M24: =LN(F24/F23) -> -0.023736985 | N24: =LN(G24/G23) -> -0.011029339 | O24: =LN(H24/H23) -> -0.0088690098 | AC24: AAPL | AD24: COST | AE24: JNJ | AF24: JPM | AG24: NEE | AH24: PG | AI24: SUM
A25: 44967 | B25: 148.99283 | C25: 480.71268 | D25: 148.01419 | E25: 131.36542 | F25: 68.494301 | G25: 128.9796 | H25: 4090.46 | I25: =LN(B25/B24) -> 0.0024532356 | J25: =LN(C25/C24) -> -0.0012793368 | K25: =LN(D25/D24) -> 0.0046357602 | L25: =LN(E25/E24) -> 0.0044055876 | M25: =LN(F25/F24) -> 0.019864318 | N25: =LN(G25/G24) -> 0.0087898712 | O25: =LN(H25/H24) -> 0.0021928557 | AB25: Weights, GMV | AC25: 0.081255948 | AD25: 0.18290363 | AE25: 0.29175639 | AF25: 0.13351579 | AG25: 0.039044501 | AH25: 0.27152373 | AI25: =SUM(AC25:AH25) -> 1
A26: 44970 | B26: 151.79488 | C26: 486.92368 | D26: 148.56192 | E26: 132.79048 | F26: 69.300774 | G26: 130.66814 | H26: 4137.29 | I26: =LN(B26/B25) -> 0.018631937 | J26: =LN(C26/C25) -> 0.012837641 | K26: =LN(D26/D25) -> 0.0036936901 | L26: =LN(E26/E25) -> 0.010789673 | M26: =LN(F26/F25) -> 0.011705527 | N26: =LN(G26/G25) -> 0.013006556 | O26: =LN(H26/H25) -> 0.01138357
A27: 44971 | B27: 151.15358 | C27: 483.81821 | D27: 147.91379 | E27: 133.37726 | F27: 69.676491 | G27: 129.93114 | H27: 4136.1299 | I27: =LN(B27/B26) -> -0.004233706 | J27: =LN(C27/C26) -> -0.0063981567 | K27: =LN(D27/D26) -> -0.0043722527 | L27: =LN(E27/E26) -> 0.0044090819 | M27: =LN(F27/F26) -> 0.0054068999 | N27: =LN(G27/G26) -> -0.0056562051 | O27: =LN(H27/H26) -> -0.00028045386 | AB27: Variance, GMV | AC27: {=MMULT(AC25:AH25,MMULT(AC13:AH18,TRANSPOSE(AC25:AH25)))} -> 0.013370003
A28: 44972 | B28: 153.25513 | C28: 491.56744 | D28: 145.47655 | E28: 133.93613 | F28: 70.510468 | G28: 129.63261 | H28: 4147.6001 | I28: =LN(B28/B27) -> 0.013807625 | J28: =LN(C28/C27) -> 0.01588992 | K28: =LN(D28/D27) -> -0.016614703 | L28: =LN(E28/E27) -> 0.0041813785 | M28: =LN(F28/F27) -> 0.011898205 | N28: =LN(G28/G27) -> -0.0023001908 | O28: =LN(H28/H27) -> 0.0027693375 | AB28: Std,GMV | AC28: =SQRT(AC27) -> 0.11562873
A29: 44973 | B29: 151.65677 | C29: 484.66434 | D29: 144.44507 | E29: 132.09192 | F29: 69.364929 | G29: 127.93477 | H29: 4090.4099 | I29: =LN(B29/B28) -> -0.010484162 | J29: =LN(C29/C28) -> -0.014142588 | K29: =LN(D29/D28) -> -0.0071156008 | L29: =LN(E29/E28) -> -0.013864984 | M29: =LN(F29/F28) -> -0.016379778 | N29: =LN(G29/G28) -> -0.01318389 | O29: =LN(H29/H28) -> -0.013884689 | AB29: Return, GMV | AC29: =SUMPRODUCT(AC25:AH25,S4:X4) -> 0.12857439
A30: 44974 | B30: 150.51227 | C30: 487.91394 | D30: 147.46065 | E30: 132.48309 | F30: 69.713173 | G30: 130.61214 | H30: 4079.0901 | I30: =LN(B30/B29) -> -0.0075752712 | J30: =LN(C30/C29) -> 0.0066824757 | K30: =LN(D30/D29) -> 0.020662059 | L30: =LN(E30/E29) -> 0.0029570034 | M30: =LN(F30/F29) -> 0.0050078975 | N30: =LN(G30/G29) -> 0.02071163 | O30: =LN(H30/H29) -> -0.0027712422 | AB30: Sharp Ratio, GMV | AC30: =(AC29-AC22)/AC28 -> 0.75132181
A31: 44978 | B31: 146.49661 | C31: 482.39526 | D31: 145.26334 | E31: 130.05217 | F31: 67.504562 | G31: 130.51883 | H31: 3997.3401 | I31: =LN(B31/B30) -> -0.027042291 | J31: =LN(C31/C30) -> -0.011375212 | K31: =LN(D31/D30) -> -0.015013137 | L31: =LN(E31/E30) -> -0.018519363 | M31: =LN(F31/F30) -> -0.032194108 | N31: =LN(G31/G30) -> -0.0007146414 | O31: =LN(H31/H30) -> -0.020244784
A32: 44979 | B32: 146.9209 | C32: 478.21295 | D32: 145.06107 | E32: 129.05551 | F32: 67.522881 | G32: 131.06926 | H32: 3991.05 | I32: =LN(B32/B31) -> 0.0028920304 | J32: =LN(C32/C31) -> -0.0087076883 | K32: =LN(D32/D31) -> -0.0013934105 | L32: =LN(E32/E31) -> -0.0076930428 | M32: =LN(F32/F31) -> 0.00027132524 | N32: =LN(G32/G31) -> 0.0042083805 | O32: =LN(H32/H31) -> -0.0015747955 | AC32: AAPL | AD32: COST | AE32: JNJ | AF32: JPM | AG32: NEE | AH32: PG | AI32: SUM
A33: 44980 | B33: 147.40433 | C33: 474.12677 | D33: 145.01509 | E33: 130.08939 | F33: 66.780579 | G33: 130.64944 | H33: 4012.3201 | I33: =LN(B33/B32) -> 0.0032850014 | J33: =LN(C33/C32) -> -0.0085814056 | K33: =LN(D33/D32) -> -0.00031698387 | L33: =LN(E33/E32) -> 0.0079791654 | M33: =LN(F33/F32) -> -0.011054213 | N33: =LN(G33/G32) -> -0.0032081423 | O33: =LN(H33/H32) -> 0.0053152783 | AB33: Weights, MSR | AC33: 0.11895743 | AD33: 0.38998297 | AE33: 0.015137779 | AF33: 0.47592183 | AG33: 0 | AH33: 0 | AI33: =SUM(AC33:AH33) -> 1
A34: 44981 | B34: 144.75027 | C34: 469.77145 | D34: 143.39696 | E34: 131.26297 | F34: 66.826393 | G34: 129.91246 | H34: 3970.04 | I34: =LN(B34/B33) -> -0.018169324 | J34: =LN(C34/C33) -> -0.0092284252 | K34: =LN(D34/D33) -> -0.011221102 | L34: =LN(E34/E33) -> 0.0089809167 | M34: =LN(F34/F33) -> 0.00068581026 | N34: =LN(G34/G33) -> -0.0056568992 | O34: =LN(H34/H33) -> -0.010593465
A35: 44984 | B35: 145.94409 | C35: 468.25244 | D35: 143.08438 | E35: 132.4086 | F35: 66.280357 | G35: 129.80052 | H35: 3982.24 | I35: =LN(B35/B34) -> 0.0082136016 | J35: =LN(C35/C34) -> -0.0032387528 | K35: =LN(D35/D34) -> -0.0021821765 | L35: =LN(E35/E34) -> 0.0086898796 | M35: =LN(F35/F34) -> -0.008204525 | N35: =LN(G35/G34) -> -0.00086201685 | O35: =LN(H35/H34) -> 0.0030682925 | AB35: Variance, MSR | AC35: {=MMULT(AC33:AH33,MMULT(AC13:AH18,TRANSPOSE(AC33:AH33)))} -> 0.026604482
A36: 44985 | B36: 145.44092 | C36: 465.51227 | D36: 140.90541 | E36: 133.51695 | F36: 65.514801 | G36: 128.32655 | H36: 3970.1499 | I36: =LN(B36/B35) -> -0.0034536734 | J36: =LN(C36/C35) -> -0.0058691042 | K36: =LN(D36/D35) -> -0.015345714 | L36: =LN(E36/E35) -> 0.0083358599 | M36: =LN(F36/F35) -> -0.011617497 | N36: =LN(G36/G35) -> -0.011420612 | O36: =LN(H36/H35) -> -0.0030406198 | AB36: Std,MSR | AC36: =SQRT(AC35) -> 0.16310881
A37: 44986 | B37: 143.36894 | C37: 460.21472 | D37: 140.27107 | E37: 132.77184 | F37: 64.44487 | G37: 128.41989 | H37: 3951.3899 | I37: =LN(B37/B36) -> -0.014348619 | J37: =LN(C37/C36) -> -0.011445284 | K37: =LN(D37/D36) -> -0.0045120378 | L37: =LN(E37/E36) -> -0.0055963237 | M37: =LN(F37/F36) -> -0.016465957 | N37: =LN(G37/G36) -> 0.00072708323 | O37: =LN(H37/H36) -> -0.0047364642 | AB37: Return, MSR | AC37: =SUMPRODUCT(AC33:AH33,S4:X4) -> 0.26914666
A38: 44987 | B38: 143.96097 | C38: 466.96405 | D38: 140.16072 | E38: 131.39337 | F38: 66.60318 | G38: 130.53749 | H38: 3981.3501 | I38: =LN(B38/B37) -> 0.0041208839 | J38: =LN(C38/C37) -> 0.014559108 | K38: =LN(D38/D37) -> -0.00078701182 | L38: =LN(E38/E37) -> -0.010436471 | M38: =LN(F38/F37) -> 0.032942194 | N38: =LN(G38/G37) -> 0.016355175 | O38: =LN(H38/H37) -> 0.0075535937 | AB38: Sharp Ratio, MSR | AC38: =(AC37-AC22)/AC36 -> 1.3944475
A39: 44988 | B39: 149.01256 | C39: 456.93622 | D39: 141.60417 | E39: 133.80571 | F39: 68.097397 | G39: 131.48903 | H39: 4045.6399 | I39: =LN(B39/B38) -> 0.034488377 | J39: =LN(C39/C38) -> -0.02170846 | K39: =LN(D39/D38) -> 0.010245872 | L39: =LN(E39/E38) -> 0.018193161 | M39: =LN(F39/F38) -> 0.022186664 | N39: =LN(G39/G38) -> 0.0072629463 | O39: =LN(H39/H38) -> 0.016018749
A40: 44991 | B40: 151.77518 | C40: 464.45468 | D40: 143.01999 | E40: 133.02335 | F40: 68.623131 | G40: 130.92934 | H40: 4048.4199 | I40: =LN(B40/B39) -> 0.018369743 | J40: =LN(C40/C39) -> 0.016320174 | K40: =LN(D40/D39) -> 0.0099487614 | L40: =LN(E40/E39) -> -0.005864175 | M40: =LN(F40/F39) -> 0.0076906745 | N40: =LN(G40/G39) -> -0.004265656 | O40: =LN(H40/H39) -> 0.00068693078
...

Sheet Part D
B1: Daily Prices | I1: Log Returns | AB1: Daily Covariance | AL1: Correlation
A2: Date | B2: AAPL | C2: COST | D2: JNJ | E2: JPM | F2: NEE | G2: PG | H2: ^GSPC | I2: AAPL | J2: COST | K2: JNJ | L2: JPM | M2: NEE | N2: PG | O2: ^GSPC | S2: AAPL | T2: COST | U2: JNJ | V2: JPM | W2: NEE | X2: PG | Y2: ^GSPC | AC2: AAPL | AD2: COST | AE2: JNJ | AF2: JPM | AG2: NEE | AH2: PG | AI2: ^GSPC | AM2: AAPL | AN2: COST | AO2: JNJ | AP2: JPM | AQ2: NEE | AR2: PG | AS2: ^GSPC
A3: 44936 | B3: 128.78706 | C3: 462.03519 | D3: 159.89003 | E3: 129.09279 | F3: 77.475365 | G3: 140.8111 | H3: 3919.25 | R3: Daily Return | S3: =AVERAGE(I4:I755) -> 0.00093097769 | T3: =AVERAGE(J4:J755) -> 0.00092290287 | U3: =AVERAGE(K4:K755) -> 0.00032652083 | V3: =AVERAGE(L4:L755) -> 0.0012448187 | W3: =AVERAGE(M4:M755) -> 4.0812061e-05 | X3: =AVERAGE(N4:N755) -> 9.9625826e-06 | Y3: =AVERAGE(O4:O755) -> 0.00076486839 | AB3: AAPL | AC3: =VARP('Part D'!$I$3:$I$755) -> 0.00025524944 | AD3: {=TRANSPOSE(AC4:AC9)} -> 6.6514618e-05 | AE3: 1.0257314e-05 | AF3: 6.9517756e-05 | AG3: 3.7287102e-05 | AH3: 2.3668654e-05 | AI3: 0.00010253729 | AL3: AAPL | AM3: 1 | AN3: {=TRANSPOSE(AM4:AM9)} -> 0.33617744 | AO3: 0.059452546 | AP3: 0.29918965 | AQ3: 0.1352244 | AR3: 0.1432866 | AS3: 0.68182721
A4: 44937 | B4: 131.50606 | C4: 464.82806 | D4: 159.63443 | E4: 130.05217 | F4: 77.896927 | G4: 139.67084 | H4: 3969.6101 | I4: =LN(B4/B3) -> 0.020892546 | J4: =LN(C4/C3) -> 0.0060265323 | K4: =LN(D4/D3) -> -0.0015998777 | L4: =LN(E4/E3) -> 0.0074042381 | M4: =LN(F4/F3) -> 0.0054264918 | N4: =LN(G4/G3) -> -0.0081307559 | O4: =LN(H4/H3) -> 0.012767571 | R4: Annual Return | S4: =S3*252 -> 0.23460638 | T4: =T3*252 -> 0.23257152 | U4: =U3*252 -> 0.082283249 | V4: =V3*252 -> 0.31369431 | W4: =W3*252 -> 0.010284639 | X4: =X3*252 -> 0.0025105708 | Y4: =Y3*252 -> 0.19274683 | AB4: COST | AC4: 6.6514618e-05 | AD4: =VARP('Part D'!$J$3:$J$755) -> 0.00015336713 | AE4: {=TRANSPOSE(AD5:AD9)} -> 1.1619868e-05 | AF4: 4.3485998e-05 | AG4: 2.0615737e-05 | AH4: 3.5350912e-05 | AI4: 5.5491219e-05 | AL4: COST | AM4: 0.33617744 | AN4: 1 | AO4: {=TRANSPOSE(AN5:AN9)} -> 0.086886886 | AP4: 0.24144405 | AQ4: 0.096452067 | AR4: 0.27608886 | AS4: 0.47602856
A5: 44938 | B5: 131.42723 | C5: 463.02371 | D5: 158.83115 | E5: 129.92177 | F5: 77.961075 | G5: 138.88284 | H5: 3983.1699 | I5: =LN(B5/B4) -> -0.00059959625 | J5: =LN(C5/C4) -> -0.0038893154 | K5: =LN(D5/D4) -> -0.0050447235 | L5: =LN(E5/E4) -> -0.00100319 | M5: =LN(F5/F4) -> 0.00082315893 | N5: =LN(G5/G4) -> -0.0056577711 | O5: =LN(H5/H4) -> 0.0034100849 | R5: Daily Std | S5: =_xlfn.STDEV.S(I4:I755) -> 0.015987161 | T5: =_xlfn.STDEV.S(J4:J755) -> 0.012392391 | U5: =_xlfn.STDEV.S(K4:K755) -> 0.01080612 | V5: =_xlfn.STDEV.S(L4:L755) -> 0.014553108 | W5: =_xlfn.STDEV.S(M4:M755) -> 0.017270708 | X5: =_xlfn.STDEV.S(N4:N755) -> 0.010346049 | Y5: =_xlfn.STDEV.S(O4:O755) -> 0.009419201 | AB5: JNJ | AC5: 1.0257314e-05 | AD5: 1.1619868e-05 | AE5: =VARP('Part D'!$K$3:$K$755) -> 0.00011661694 | AF5: {=TRANSPOSE(AE6:AE9)} -> 2.3789911e-05 | AG5: 5.0082259e-05 | AH5: 4.0289905e-05 | AI5: 8.2572266e-06 | AL5: JNJ | AM5: 0.059452546 | AN5: 0.086886886 | AO5: 1 | AP5: {=TRANSPOSE(AO6:AO9)} -> 0.15147648 | AQ5: 0.26870881 | AR5: 0.36085259 | AS5: 0.08123221
A6: 44939 | B6: 132.75719 | C6: 465.73029 | D6: 158.31082 | E6: 133.20027 | F6: 77.603653 | G6: 139.8748 | H6: 3999.0901 | I6: =LN(B6/B5) -> 0.010068476 | J6: =LN(C6/C5) -> 0.0058284135 | K6: =LN(D6/D5) -> -0.0032813391 | L6: =LN(E6/E5) -> 0.024921311 | M6: =LN(F6/F5) -> -0.0045951612 | N6: =LN(G6/G5) -> 0.0071170267 | O6: =LN(H6/H5) -> 0.0039888921 | R6: Annual Std | S6: =S5*SQRT(252) -> 0.25378831 | T6: =T5*SQRT(252) -> 0.1967231 | U6: =U5*SQRT(252) -> 0.17154183 | V6: =V5*SQRT(252) -> 0.23102342 | W6: =W5*SQRT(252) -> 0.27416399 | X6: =X5*SQRT(252) -> 0.16423844 | Y6: =Y5*SQRT(252) -> 0.14952518 | AB6: JPM | AC6: 6.9517756e-05 | AD6: 4.3485998e-05 | AE6: 2.3789911e-05 | AF6: =VARP('Part D'!$L$3:$L$755) -> 0.0002115113 | AG6: {=TRANSPOSE(AF7:AF9)} -> 2.8469214e-05 | AH6: 1.1642316e-05 | AI6: 8.213032e-05 | AL6: JPM | AM6: 0.29918965 | AN6: 0.24144405 | AO6: 0.15147648 | AP6: 1 | AQ6: {=TRANSPOSE(AP7:AP9)} -> 0.11341944 | AR6: 0.077426031 | AS6: 0.59994524
A7: 44943 | B7: 133.91966 | C7: 467.18915 | D7: 157.33412 | E7: 131.14189 | F7: 78.575066 | G7: 139.46687 | H7: 3990.97 | I7: =LN(B7/B6) -> 0.0087182892 | J7: =LN(C7/C6) -> 0.003127523 | K7: =LN(D7/D6) -> -0.0061886177 | L7: =LN(E7/E6) -> -0.015573919 | M7: =LN(F7/F6) -> 0.012439917 | N7: =LN(G7/G6) -> -0.0029206437 | O7: =LN(H7/H6) -> -0.0020325554 | AB7: NEE | AC7: 3.7287102e-05 | AD7: 2.0615737e-05 | AE7: 5.0082259e-05 | AF7: 2.8469214e-05 | AG7: =VARP('Part D'!$M$3:$M$755) -> 0.0002978807 | AH7: {=TRANSPOSE(AG8:AG9)} -> 5.9700694e-05 | AI7: 3.8027351e-05 | AL7: NEE | AM7: 0.1352244 | AN7: 0.096452067 | AO7: 0.26870881 | AP7: 0.11341944 | AQ7: 1 | AR7: {=TRANSPOSE(AQ8:AQ9)} -> 0.33455891 | AS7: 0.23407216
A8: 44944 | B8: 133.20052 | C8: 460.18277 | D8: 154.96078 | E8: 127.20205 | F8: 76.797203 | G8: 135.73082 | H8: 3928.8601 | I8: =LN(B8/B7) -> -0.0053844563 | J8: =LN(C8/C7) -> -0.015110467 | K8: =LN(D8/D7) -> -0.015199623 | L8: =LN(E8/E7) -> -0.030503117 | M8: =LN(F8/F7) -> -0.022886197 | N8: =LN(G8/G7) -> -0.027153447 | O8: =LN(H8/H7) -> -0.015684967 | AB8: PG | AC8: 2.3668654e-05 | AD8: 3.5350912e-05 | AE8: 4.0289905e-05 | AF8: 1.1642316e-05 | AG8: 5.9700694e-05 | AH8: =VARP('Part D'!$N$3:$N$755) -> 0.0001068984 | AI8: =AH9 -> 1.4427467e-05 | AL8: PG | AM8: 0.1432866 | AN8: 0.27608886 | AO8: 0.36085259 | AP8: 0.077426031 | AQ8: 0.33455891 | AR8: 1 | AS8: =AR9 -> 0.14824477
A9: 44945 | B9: 133.25963 | C9: 450.60422 | D9: 154.75085 | E9: 125.50687 | F9: 75.688316 | G9: 132.86037 | H9: 3898.8501 | I9: =LN(B9/B8) -> 0.00044368774 | J9: =LN(C9/C8) -> -0.021034348 | K9: =LN(D9/D8) -> -0.001355651 | L9: =LN(E9/E8) -> -0.013416291 | M9: =LN(F9/F8) -> -0.014544414 | N9: =LN(G9/G8) -> -0.021374954 | O9: =LN(H9/H8) -> -0.0076676719 | AB9: ^GSPC | AC9: 0.00010253729 | AD9: 5.5491219e-05 | AE9: 8.2572266e-06 | AF9: 8.213032e-05 | AG9: 3.8027351e-05 | AH9: 1.4427467e-05 | AI9: =VARP('Part D'!$O$3:$O$755) -> 8.8603368e-05 | AL9: ^GSPC | AM9: 0.68182721 | AN9: 0.47602856 | AO9: 0.08123221 | AP9: 0.59994524 | AQ9: 0.23407216 | AR9: 0.14824477 | AS9: 1
A10: 44946 | B10: 135.82098 | C10: 460.79697 | D10: 154.02974 | E10: 125.81425 | F10: 74.982658 | G10: 133.37346 | H10: 3972.6101 | I10: =LN(B10/B9) -> 0.019038406 | J10: =LN(C10/C9) -> 0.022368139 | K10: =LN(D10/D9) -> -0.0046707367 | L10: =LN(E10/E9) -> 0.0024461809 | M10: =LN(F10/F9) -> -0.0093669417 | N10: =LN(G10/G9) -> 0.0038544514 | O10: =LN(H10/H9) -> 0.018741674
A11: 44949 | B11: 139.01282 | C11: 472.79422 | D11: 153.63719 | E11: 127.854 | F11: 75.761627 | G11: 131.58232 | H11: 4019.8101 | I11: =LN(B11/B10) -> 0.023228417 | J11: =LN(C11/C10) -> 0.025702715 | K11: =LN(D11/D10) -> -0.0025517713 | L11: =LN(E11/E10) -> 0.016082368 | M11: =LN(F11/F10) -> 0.010335062 | N11: =LN(G11/G10) -> -0.013520482 | O11: =LN(H11/H10) -> 0.011811316 | AB11: Annual Covariance
A12: 44950 | B12: 140.41174 | C12: 472.31433 | D12: 153.63719 | E12: 128.95308 | F12: 76.88884 | G12: 132.30061 | H12: 4016.95 | I12: =LN(B12/B11) -> 0.010012989 | J12: =LN(C12/C11) -> -0.0010155214 | K12: =LN(D12/D11) -> 0 | L12: =LN(E12/E11) -> 0.0085595928 | M12: =LN(F12/F11) -> 0.014768812 | N12: =LN(G12/G11) -> 0.0054440353 | O12: =LN(H12/H11) -> -0.00071175636 | AC12: AAPL | AD12: COST | AE12: JNJ | AF12: JPM | AG12: NEE | AH12: PG | AI12: ^GSPC
A13: 44951 | B13: 139.75166 | C13: 471.13379 | D13: 154.7326 | E13: 129.57712 | F13: 70.189705 | G13: 132.20737 | H13: 4016.22 | I13: =LN(B13/B12) -> -0.0047121156 | J13: =LN(C13/C12) -> -0.0025026127 | K13: =LN(D13/D12) -> 0.0071045727 | L13: =LN(E13/E12) -> 0.0048275978 | M13: =LN(F13/F12) -> -0.091159092 | N13: =LN(G13/G12) -> -0.00070505596 | O13: =LN(H13/H12) -> -0.00018174157 | AB13: AAPL | AC13: =AC3*252 -> 0.064322858 | AD13: =AD3*252 -> 0.016761684 | AE13: =AE3*252 -> 0.0025848432 | AF13: =AF3*252 -> 0.017518475 | AG13: =AG3*252 -> 0.0093963498 | AH13: =AH3*252 -> 0.0059645008 | AI13: =AI3*252 -> 0.025839397
A14: 44952 | B14: 141.82047 | C14: 478.25525 | D14: 154.16664 | E14: 130.37813 | F14: 70.015587 | G14: 131.67558 | H14: 4060.4299 | I14: =LN(B14/B13) -> 0.014694914 | J14: =LN(C14/C13) -> 0.015002477 | K14: =LN(D14/D13) -> -0.0036643947 | L14: =LN(E14/E13) -> 0.0061626967 | M14: =LN(F14/F13) -> -0.0024837598 | N14: =LN(G14/G13) -> -0.0040304595 | O14: =LN(H14/H13) -> 0.010947708 | AB14: COST | AC14: =AC4*252 -> 0.016761684 | AD14: =AD4*252 -> 0.038648516 | AE14: =AE4*252 -> 0.0029282067 | AF14: =AF4*252 -> 0.010958471 | AG14: =AG4*252 -> 0.0051951657 | AH14: =AH4*252 -> 0.0089084298 | AI14: =AI4*252 -> 0.013983787
A15: 44953 | B15: 143.76117 | C15: 483.04465 | D15: 153.56416 | E15: 130.69481 | F15: 69.264107 | G15: 131.13455 | H15: 4070.5601 | I15: =LN(B15/B14) -> 0.01359145 | J15: =LN(C15/C14) -> 0.0099645029 | K15: =LN(D15/D14) -> -0.0039156223 | L15: =LN(E15/E14) -> 0.0024259969 | M15: =LN(F15/F14) -> -0.010791055 | N15: =LN(G15/G14) -> -0.0041172815 | O15: =LN(H15/H14) -> 0.002491734 | AB15: JNJ | AC15: =AC5*252 -> 0.0025848432 | AD15: =AD5*252 -> 0.0029282067 | AE15: =AE5*252 -> 0.029387469 | AF15: =AF5*252 -> 0.0059950575 | AG15: =AG5*252 -> 0.012620729 | AH15: =AH5*252 -> 0.010153056 | AI15: =AI5*252 -> 0.0020808211
A16: 44956 | B16: 140.87473 | C16: 483.03497 | D16: 147.87727 | E16: 129.58646 | F16: 68.778397 | G16: 131.545 | H16: 4017.77 | I16: =LN(B16/B15) -> -0.020282354 | J16: =LN(C16/C15) -> -2.0027484e-05 | K16: =LN(D16/D15) -> -0.037735784 | L16: =LN(E16/E15) -> -0.008516628 | M16: =LN(F16/F15) -> -0.0070371391 | N16: =LN(G16/G15) -> 0.0031250739 | O16: =LN(H16/H15) -> -0.013053569 | AB16: JPM | AC16: =AC6*252 -> 0.017518475 | AD16: =AD6*252 -> 0.010958471 | AE16: =AE6*252 -> 0.0059950575 | AF16: =AF6*252 -> 0.053300847 | AG16: =AG6*252 -> 0.007174242 | AH16: =AH6*252 -> 0.0029338636 | AI16: =AI6*252 -> 0.020696841
A17: 44957 | B17: 142.14555 | C17: 490.5788 | D17: 149.17349 | E17: 130.35948 | F17: 68.393501 | G17: 132.82303 | H17: 4076.6001 | I17: =LN(B17/B16) -> 0.0089805352 | J17: =LN(C17/C16) -> 0.015496852 | K17: =LN(D17/D16) -> 0.0087273103 | L17: =LN(E17/E16) -> 0.0059476043 | M17: =LN(F17/F16) -> -0.0056118832 | N17: =LN(G17/G16) -> 0.0096686454 | O17: =LN(H17/H16) -> 0.014536304 | AB17: NEE | AC17: =AC7*252 -> 0.0093963498 | AD17: =AD7*252 -> 0.0051951657 | AE17: =AE7*252 -> 0.012620729 | AF17: =AF7*252 -> 0.007174242 | AG17: =AG7*252 -> 0.075065937 | AH17: =AH7*252 -> 0.015044575 | AI17: =AI7*252 -> 0.0095828924 | AP17: PART D
A18: 44958 | B18: 143.26862 | C18: 497.07657 | D18: 150.54272 | E18: 130.01489 | F18: 68.036079 | G18: 133.57867 | H18: 4119.21 | I18: =LN(B18/B17) -> 0.0078697419 | J18: =LN(C18/C17) -> 0.013158165 | K18: =LN(D18/D17) -> 0.009136921 | L18: =LN(E18/E17) -> -0.0026468767 | M18: =LN(F18/F17) -> -0.0052396656 | N18: =LN(G18/G17) -> 0.0056729951 | O18: =LN(H18/H17) -> 0.010398056 | AB18: PG | AC18: =AC8*252 -> 0.0059645008 | AD18: =AD8*252 -> 0.0089084298 | AE18: =AE8*252 -> 0.010153056 | AF18: =AF8*252 -> 0.0029338636 | AG18: =AG8*252 -> 0.015044575 | AH18: =AH8*252 -> 0.026938396 | AI18: =AI8*252 -> 0.0036357217
A19: 44959 | B19: 148.57854 | C19: 503.24899 | D19: 151.10867 | E19: 129.40947 | F19: 69.282433 | G19: 132.62714 | H19: 4179.7598 | I19: =LN(B19/B18) -> 0.036392387 | J19: =LN(C19/C18) -> 0.012340988 | K19: =LN(D19/D18) -> 0.003752339 | L19: =LN(E19/E18) -> -0.0046674419 | M19: =LN(F19/F18) -> 0.018153232 | N19: =LN(G19/G18) -> -0.0071489209 | O19: =LN(H19/H18) -> 0.014592385 | AB19: ^GSPC | AC19: =AC9*252 -> 0.025839397 | AD19: =AD9*252 -> 0.013983787 | AE19: =AE9*252 -> 0.0020808211 | AF19: =AF9*252 -> 0.020696841 | AG19: =AG9*252 -> 0.0095828924 | AH19: =AH9*252 -> 0.0036357217 | AI19: =AI9*252 -> 0.022328049
A20: 44960 | B20: 152.20383 | C20: 494.95175 | D20: 150.25975 | E20: 131.412 | F20: 68.430153 | G20: 133.0376 | H20: 4136.48 | I20: =LN(B20/B19) -> 0.024106902 | J20: =LN(C20/C19) -> -0.016624777 | K20: =LN(D20/D19) -> -0.0056338017 | L20: =LN(E20/E19) -> 0.015355885 | M20: =LN(F20/F19) -> -0.012377816 | N20: =LN(G20/G19) -> 0.0030900733 | O20: =LN(H20/H19) -> -0.010408593 | AV20: For Each constructed portfolio
A21: 44963 | B21: 149.47498 | C21: 495.7113 | D21: 149.11871 | E21: 132.18503 | F21: 69.199974 | G21: 131.90883 | H21: 4111.0801 | I21: =LN(B21/B20) -> -0.018091598 | J21: =LN(C21/C20) -> 0.0015334218 | K21: =LN(D21/D20) -> -0.0076227428 | L21: =LN(E21/E20) -> 0.0058652233 | M21: =LN(F21/F20) -> 0.011186929 | N21: =LN(G21/G20) -> -0.0085207849 | O21: =LN(H21/H20) -> -0.0061593932 | AM21: For Individual stocks
A22: 44964 | B22: 152.35156 | C22: 496.61505 | D22: 149.15524 | E22: 133.79636 | F22: 69.722321 | G22: 130.62144 | H22: 4164 | I22: =LN(B22/B21) -> 0.01906177 | J22: =LN(C22/C21) -> 0.001821473 | K22: =LN(D22/D21) -> 0.00024493953 | L22: =LN(E22/E21) -> 0.012116245 | M22: =LN(F22/F21) -> 0.0075200163 | N22: =LN(G22/G21) -> -0.0098075878 | O22: =LN(H22/H21) -> 0.012790364 | AB22: Risk free return | AC22: 0.0417
A23: 44965 | B23: 149.66217 | C23: 484.38541 | D23: 149.34692 | E23: 132.85567 | F23: 68.760071 | G23: 129.26877 | H23: 4117.8599 | I23: =LN(B23/B22) -> -0.017810205 | J23: =LN(C23/C22) -> -0.024934297 | K23: =LN(D23/D22) -> 0.001284285 | L23: =LN(E23/E22) -> -0.0070555849 | M23: =LN(F23/F22) -> -0.013897294 | N23: =LN(G23/G22) -> -0.010409693 | O23: =LN(H23/H22) -> -0.011142573 | Z23: Without short selling
A24: 44966 | B24: 148.62776 | C24: 481.32806 | D24: 147.32962 | E24: 130.78795 | F24: 67.147133 | G24: 127.85085 | H24: 4081.5 | I24: =LN(B24/B23) -> -0.0069356194 | J24: =LN(C24/C23) -> -0.006331801 | K24: =LN(D24/D23) -> -0.013599555 | L24: =LN(E24/E23) -> -0.015686031 | M24: =LN(F24/F23) -> -0.023736985 | N24: =LN(G24/G23) -> -0.011029339 | O24: =LN(H24/H23) -> -0.0088690098 | AC24: AAPL | AD24: COST | AE24: JNJ | AF24: JPM | AG24: NEE | AH24: PG | AI24: SUM | AM24: AAPL | AN24: COST | AO24: JNJ | AP24: JPM | AQ24: NEE | AR24: PG | AW24: Beta | AX24: CAPM E[R] | AY24: Jensen's Alpha | AZ24: Systematic Risk | BA24: Idiosyncratic Risk
A25: 44967 | B25: 148.99283 | C25: 480.71268 | D25: 148.01419 | E25: 131.36542 | F25: 68.494301 | G25: 128.9796 | H25: 4090.46 | I25: =LN(B25/B24) -> 0.0024532356 | J25: =LN(C25/C24) -> -0.0012793368 | K25: =LN(D25/D24) -> 0.0046357602 | L25: =LN(E25/E24) -> 0.0044055876 | M25: =LN(F25/F24) -> 0.019864318 | N25: =LN(G25/G24) -> 0.0087898712 | O25: =LN(H25/H24) -> 0.0021928557 | AB25: Weights, GMV | AC25: 0.081255948 | AD25: 0.18290363 | AE25: 0.29175639 | AF25: 0.13351579 | AG25: 0.039044501 | AH25: 0.27152373 | AI25: =SUM(AC25:AH25) -> 1 | AL25: Beta | AM25: =AI13/AI19 -> 1.1572618 | AN25: =AI14/AI19 -> 0.62628793 | AO25: =AI15/AI19 -> 0.093193147 | AP25: =AI16/AI19 -> 0.92694354 | AQ25: =AI17/AI19 -> 0.42918629 | AR25: =AI18/AI19 -> 0.16283204 | AU25: without short selling | AV25: GMV | AW25: =SUMPRODUCT(AM25:AR25,AC25:AH25) -> 0.42050617 | AX25: =SUMPRODUCT($AM$26:$AR$26,AC25:AH25) -> 0.10521612 | AY25: =SUMPRODUCT($AM$27:$AR$27,AC25:AH25) -> 0.023358262 | AZ25: =SUMPRODUCT($AM$28:$AR$28,AC25:AH25) -> 0.062876261 | BA25: =SUMPRODUCT($AM$29:$AR$29,AC25:AH25) -> 0.17579784
A26: 44970 | B26: 151.79488 | C26: 486.92368 | D26: 148.56192 | E26: 132.79048 | F26: 69.300774 | G26: 130.66814 | H26: 4137.29 | I26: =LN(B26/B25) -> 0.018631937 | J26: =LN(C26/C25) -> 0.012837641 | K26: =LN(D26/D25) -> 0.0036936901 | L26: =LN(E26/E25) -> 0.010789673 | M26: =LN(F26/F25) -> 0.011705527 | N26: =LN(G26/G25) -> 0.013006556 | O26: =LN(H26/H25) -> 0.01138357 | AL26: CAPM E[R] | AM26: =$AC$22+(AM25*($Y$4-$AC$22)) -> 0.21650073 | AN26: =$AC$22+(AN25*($Y$4-$AC$22)) -> 0.13629881 | AO26: =$AC$22+(AO25*($Y$4-$AC$22)) -> 0.05577653 | AP26: =$AC$22+(AP25*($Y$4-$AC$22)) -> 0.18171189 | AQ26: =$AC$22+(AQ25*($Y$4-$AC$22)) -> 0.10652723 | AR26: =$AC$22+(AR25*($Y$4-$AC$22)) -> 0.066295264 | AV26: MSR | AW26: =SUMPRODUCT(AM25:AR25,AC33:AH33) -> 0.82446991 | AX26: =SUMPRODUCT($AM$26:$AR$26,AC33:AH33) -> 0.16623357 | AY26: =SUMPRODUCT($AM$27:$AR$27,AC33:AH33) -> 0.10291309 | AZ26: =SUMPRODUCT($AM$28:$AR$28,AC33:AH33) -> 0.12327901 | BA26: =SUMPRODUCT(AM29:AR29,AC33:AH33) -> 0.18010503
A27: 44971 | B27: 151.15358 | C27: 483.81821 | D27: 147.91379 | E27: 133.37726 | F27: 69.676491 | G27: 129.93114 | H27: 4136.1299 | I27: =LN(B27/B26) -> -0.004233706 | J27: =LN(C27/C26) -> -0.0063981567 | K27: =LN(D27/D26) -> -0.0043722527 | L27: =LN(E27/E26) -> 0.0044090819 | M27: =LN(F27/F26) -> 0.0054068999 | N27: =LN(G27/G26) -> -0.0056562051 | O27: =LN(H27/H26) -> -0.00028045386 | AB27: Variance, GMV | AC27: {=MMULT(AC25:AH25,MMULT(AC13:AH18,TRANSPOSE(AC25:AH25)))} -> 0.013370003 | AL27: Jensen's Alpha | AM27: =S4-AM26 -> 0.01810565 | AN27: =T4-AN26 -> 0.096272714 | AO27: =U4-AO26 -> 0.02650672 | AP27: =V4-AP26 -> 0.13198243 | AQ27: =W4-AQ26 -> -0.096242591 | AR27: =X4-AR26 -> -0.063784693
A28: 44972 | B28: 153.25513 | C28: 491.56744 | D28: 145.47655 | E28: 133.93613 | F28: 70.510468 | G28: 129.63261 | H28: 4147.6001 | I28: =LN(B28/B27) -> 0.013807625 | J28: =LN(C28/C27) -> 0.01588992 | K28: =LN(D28/D27) -> -0.016614703 | L28: =LN(E28/E27) -> 0.0041813785 | M28: =LN(F28/F27) -> 0.011898205 | N28: =LN(G28/G27) -> -0.0023001908 | O28: =LN(H28/H27) -> 0.0027693375 | AB28: Std,GMV | AC28: =SQRT(AC27) -> 0.11562873 | AL28: Systematic Risk | AM28: =(AM25)*$Y$6 -> 0.17303978 | AN28: =(AN25)*$Y$6 -> 0.093645815 | AO28: =(AO25)*$Y$6 -> 0.013934722 | AP28: =(AP25)*$Y$6 -> 0.1386014 | AQ28: =(AQ25)*$Y$6 -> 0.064174158 | AR28: =(AR25)*$Y$6 -> 0.02434749 | AU28: with short selling | AV28: GMV | AW28: =SUMPRODUCT(AM25:AR25,AC47:AH47) -> 0.42047937 | AX28: =SUMPRODUCT($AM$26:$AR$26,AC47:AH47) -> 0.10521204 | AY28: =SUMPRODUCT($AM$27:$AR$27,AC47:AH47) -> 0.023358559 | AZ28: =SUMPRODUCT($AM$28:$AR$28,AC47:AH47) -> 0.062872255 | BA28: =SUMPRODUCT($AM$29:$AR$29,AC47:AH47) -> 0.17579768
A29: 44973 | B29: 151.65677 | C29: 484.66434 | D29: 144.44507 | E29: 132.09192 | F29: 69.364929 | G29: 127.93477 | H29: 4090.4099 | I29: =LN(B29/B28) -> -0.010484162 | J29: =LN(C29/C28) -> -0.014142588 | K29: =LN(D29/D28) -> -0.0071156008 | L29: =LN(E29/E28) -> -0.013864984 | M29: =LN(F29/F28) -> -0.016379778 | N29: =LN(G29/G28) -> -0.01318389 | O29: =LN(H29/H28) -> -0.013884689 | AB29: Return, GMV | AC29: =SUMPRODUCT(AC25:AH25,S4:X4) -> 0.12857439 | AL29: Idiosyncratic Risk | AM29: =SQRT((S6^2)-(AM28^2)) -> 0.18564952 | AN29: =SQRT((T6^2)-(AN28^2)) -> 0.17300416 | AO29: =SQRT((U6^2)-(AO28^2)) -> 0.17097492 | AP29: =SQRT((V6^2)-(AP28^2)) -> 0.18482822 | AQ29: =SQRT((W6^2)-(AQ28^2)) -> 0.2665475 | AR29: =SQRT((X6^2)-(AR28^2)) -> 0.16242372 | AV29: MSR | AW29: =SUMPRODUCT(AM25:AR25,AC55:AH55) -> 1.0628512 | AX29: =SUMPRODUCT($AM$26:$AR$26,AC55:AH55) -> 0.20224032 | AY29: =SUMPRODUCT($AM$27:$AR$27,AC55:AH55) -> 0.19978676 | AZ29: =SUMPRODUCT($AM$28:$AR$28,AC55:AH55) -> 0.15892303 | BA29: =SUMPRODUCT($AM$29:$AR$29,AC55:AH55) -> 0.17704698
A30: 44974 | B30: 150.51227 | C30: 487.91394 | D30: 147.46065 | E30: 132.48309 | F30: 69.713173 | G30: 130.61214 | H30: 4079.0901 | I30: =LN(B30/B29) -> -0.0075752712 | J30: =LN(C30/C29) -> 0.0066824757 | K30: =LN(D30/D29) -> 0.020662059 | L30: =LN(E30/E29) -> 0.0029570034 | M30: =LN(F30/F29) -> 0.0050078975 | N30: =LN(G30/G29) -> 0.02071163 | O30: =LN(H30/H29) -> -0.0027712422 | AB30: Sharp Ratio, GMV | AC30: =(AC29-AC22)/AC28 -> 0.75132181
